<?xml version="1.0" ?>
<!-- This URDF was automatically created by SolidWorks to URDF Exporter! Originally created by Stephen Brawner (brawner@gmail.com) 
     Commit Version: 1.5.1-0-g916b5db  Build Version: 1.5.7152.31018
     For more information, please see http://wiki.ros.org/sw_urdf_exporter -->
<robot
  name="shigu">
  <link
    name="base_link">
    <inertial>
      <origin
        xyz="0.028823 0.0035975 0.22447"
        rpy="0 0 0" />
      <mass
        value="34.988" />
      <inertia
        ixx="1.185"
        ixy="1.4336E-08"
        ixz="0.0004173"
        iyy="0.7989"
        iyz="-8.2142E-07"
        izz="1.901" />
    </inertial>
    <visual>
      <origin
        xyz="0 0 0"
        rpy="0 0 0" />
      <geometry>
        <mesh
          filename="package://shigu_description/meshes/base_link.STL" />
      </geometry>
      <material
        name="">
        <color
          rgba="127 127 127 1" />
      </material>
    </visual>
    <collision>
      <origin
        xyz="0 0 0"
        rpy="0 0 0" />
      <geometry>
        <mesh
          filename="package://shigu_description/meshes/base_link.STL" />
      </geometry>
    </collision>
  </link>

    <!-- Base footprint is on the ground under the robot -->
  <link name="base_footprint"/>

  <joint name="base_footprint_joint" type="fixed">
    <origin xyz="0 0 -0.127" rpy="0 0 0" />
    <parent link="base_link" />
    <child link="base_footprint" />
  </joint>

  <!-- Inertial link stores the robot's inertial information -->
  <link name="inertial_link">
    <inertial>
      <mass value="46.034" />
      <origin xyz="-0.00065 -0.085 0.062" />
      <inertia ixx="0.6022" ixy="-0.02364" ixz="-0.1197" iyy="1.7386" iyz="-0.001544" izz="2.0296" />
    </inertial>
  </link>

  <joint name="inertial_joint" type="fixed">
    <origin xyz="0 0 0" rpy="0 0 0" />
    <parent link="base_link" />
    <child link="inertial_link" />
  </joint>


  <link
    name="front_left_Link">
    <inertial>
      <origin
        xyz="-1.0381E-14 0.077449 -6.3283E-15"
        rpy="0 0 0" />
      <mass
        value="26.853" />
      <inertia
        ixx="0.1921"
        ixy="3.1242E-16"
        ixz="-8.6014E-11"
        iyy="0.27647"
        iyz="2.9337E-16"
        izz="0.1921" />
    </inertial>
    <visual>
      <origin
        xyz="0 0 0"
        rpy="0 0 0" />
      <geometry>
        <mesh
          filename="package://shigu_description/meshes/front_left_Link.STL" />
      </geometry>
      <material
        name="">
        <color
          rgba="0 0 0 1" />
      </material>
    </visual>
    <collision>
      <origin
        xyz="0 0 0"
        rpy="0 0 0" />
      <geometry>
        <mesh
          filename="package://shigu_description/meshes/front_left_Link.STL" />
      </geometry>
    </collision>
  </link>
  <joint
    name="front_left_joint"
    type="continuous">
    <origin
      xyz="0.474205261828668 0.546690227728963 -0.0237551870905212"
      rpy="0 0 0" />
    <parent
      link="base_link" />
    <child
      link="front_left_Link" />
    <axis
      xyz="0 1 0" />
  </joint>
  <link
    name="front_right_Link">
    <inertial>
      <origin
        xyz="3.3307E-16 -0.077449 1.1102E-16"
        rpy="0 0 0" />
      <mass
        value="26.853" />
      <inertia
        ixx="0.1921"
        ixy="-3.7951E-16"
        ixz="-9.8199E-11"
        iyy="0.27647"
        iyz="-4.905E-16"
        izz="0.1921" />
    </inertial>
    <visual>
      <origin
        xyz="0 0 0"
        rpy="0 0 0" />
      <geometry>
        <mesh
          filename="package://shigu_description/meshes/front_right_Link.STL" />
      </geometry>
      <material
        name="">
        <color
          rgba="0 0 0 1" />
      </material>
    </visual>
    <collision>
      <origin
        xyz="0 0 0"
        rpy="0 0 0" />
      <geometry>
        <mesh
          filename="package://shigu_description/meshes/front_right_Link.STL" />
      </geometry>
    </collision>
  </link>
  <joint
    name="front_right_joint"
    type="continuous">
    <origin
      xyz="0.474205261828672 -0.547309772271039 -0.0237551870905183"
      rpy="0 0 0" />
    <parent
      link="base_link" />
    <child
      link="front_right_Link" />
    <axis
      xyz="0 1 0" />
  </joint>
  <link
    name="rear_left_Link">
    <inertial>
      <origin
        xyz="-2.2204E-16 0.077449 0"
        rpy="0 0 0" />
      <mass
        value="26.853" />
      <inertia
        ixx="0.1921"
        ixy="3.4985E-16"
        ixz="4.0527E-14"
        iyy="0.27647"
        iyz="2.0244E-16"
        izz="0.1921" />
    </inertial>
    <visual>
      <origin
        xyz="0 0 0"
        rpy="0 0 0" />
      <geometry>
        <mesh
          filename="package://shigu_description/meshes/rear_left_Link.STL" />
      </geometry>
      <material
        name="">
        <color
          rgba="0 0 0 1" />
      </material>
    </visual>
    <collision>
      <origin
        xyz="0 0 0"
        rpy="0 0 0" />
      <geometry>
        <mesh
          filename="package://shigu_description/meshes/rear_left_Link.STL" />
      </geometry>
    </collision>
  </link>
  <joint
    name="rear_left_joint"
    type="continuous">
    <origin
      xyz="-0.480930081717801 0.546690227728961 -0.0303957072721924"
      rpy="0 0 0" />
    <parent
      link="base_link" />
    <child
      link="rear_left_Link" />
    <axis
      xyz="0 1 0" />
  </joint>
  <link
    name="rear_right_Link">
    <inertial>
      <origin
        xyz="2.2204E-16 -0.077449 -1.1102E-16"
        rpy="0 0 0" />
      <mass
        value="26.853" />
      <inertia
        ixx="0.1921"
        ixy="-4.0883E-16"
        ixz="-5.5721E-11"
        iyy="0.27647"
        iyz="-2.247E-16"
        izz="0.1921" />
    </inertial>
    <visual>
      <origin
        xyz="0 0 0"
        rpy="0 0 0" />
      <geometry>
        <mesh
          filename="package://shigu_description/meshes/rear_right_Link.STL" />
      </geometry>
      <material
        name="">
        <color
          rgba="0 0 0 1" />
      </material>
    </visual>
    <collision>
      <origin
        xyz="0 0 0"
        rpy="0 0 0" />
      <geometry>
        <mesh
          filename="package://shigu_description/meshes/rear_right_Link.STL" />
      </geometry>
    </collision>
  </link>
  <joint
    name="rear_right_joint"
    type="continuous">
    <origin
      xyz="-0.480930081717802 -0.547309772271039 -0.0303957072721914"
      rpy="0 0 0" />
    <parent
      link="base_link" />
    <child
      link="rear_right_Link" />
    <axis
      xyz="0 1 0" />
  </joint>

  <link
    name="lidar1_link">
    <inertial>
      <origin
        xyz="-0.45135 0.00085985 -0.380001"
        rpy="0 0 0" />
      <mass
        value="1.0603" />
      <inertia
        ixx="0.5"
        ixy="0"
        ixz="0"
        iyy="0.9"
        iyz="0"
        izz="0.5" />
    </inertial>
    <visual>
      <origin
        xyz="0 0 0"
        rpy="0 0 0" />
      <geometry>
        <mesh
          filename="package://shigu_description/meshes/lidar1_link.STL" />
      </geometry>
      <material
        name="">
        <color
           rgba="0 0 0 1" />
      </material>
    </visual>
    <collision>
      <origin
        xyz="0 0 0"
        rpy="0 0 0" />
      <geometry>
        <mesh
          filename="package://shigu_description/meshes/lidar1_link.STL" />
      </geometry>
    </collision>
  </link>

    <joint
    name="lidar1_joint"
    type="fixed">
    <origin
      xyz="0.45135 -0.00085982 0.420001"
      rpy="0 0 0" />
    <parent
      link="base_link" />
    <child
      link="lidar1_link" />
    <axis
      xyz="0 1 0" />
  </joint>

    <link name="imu_link"/>
  <joint name="imu_joint" type="fixed">
    <origin xyz=" 0.19 0 0.149" rpy=" 0 -1.5708 3.1416" />
    <parent link="base_link" />
    <child link="imu_link" />
  </joint>
  <gazebo reference="imu_link">
  </gazebo>


  <!-- color in gazebo -->
  <gazebo reference="base_link">
    <material>Gazebo/White</material>
  </gazebo>
  <gazebo reference="front_left_Link">
    <material>Gazebo/Black</material>
  </gazebo>
  <gazebo reference="rear_left_Link">
    <material>Gazebo/Black</material>
  </gazebo>
  <gazebo reference="front_right_Link">
    <material>Gazebo/Black</material>
  </gazebo>
  <gazebo reference="rear_right_Link">
    <material>Gazebo/Black</material>
  </gazebo>
  <gazebo reference="lidar1_link">
    <material>Gazebo/Black</material>
  </gazebo>
  <gazebo reference="imu_link">
    <material>Gazebo/Black</material>
  </gazebo>

<!-- motors and transmissions for the six wheels -->
  <transmission name="tran1">
    <type>transmission_interface/SimpleTransmission</type>
    <joint name="front_left_joint">
      <hardwareInterface>hardware_interface/VelocityJointInterface</hardwareInterface>
    </joint>
    <actuator name="motor1">
      <hardwareInterface>hardware_interface/VelocityJointInterface</hardwareInterface>
      <mechanicalReduction>1</mechanicalReduction>
    </actuator>
  </transmission>  

  <transmission name="tran2">
    <type>transmission_interface/SimpleTransmission</type>
    <joint name="rear_left_joint">
      <hardwareInterface>hardware_interface/VelocityJointInterface</hardwareInterface>
    </joint>
    <actuator name="motor2">
      <hardwareInterface>hardware_interface/VelocityJointInterface</hardwareInterface>
      <mechanicalReduction>1</mechanicalReduction>
    </actuator>
  </transmission>  

  <transmission name="tran3">
    <type>transmission_interface/SimpleTransmission</type>
    <joint name="front_right_joint">
      <hardwareInterface>hardware_interface/VelocityJointInterface</hardwareInterface>
    </joint>
    <actuator name="motor3">
      <hardwareInterface>hardware_interface/VelocityJointInterface</hardwareInterface>
      <mechanicalReduction>1</mechanicalReduction>
    </actuator>
  </transmission>  

  <transmission name="tran4">
    <type>transmission_interface/SimpleTransmission</type>
    <joint name="rear_right_joint">
      <hardwareInterface>hardware_interface/VelocityJointInterface</hardwareInterface>
    </joint>
    <actuator name="motor4">
      <hardwareInterface>hardware_interface/VelocityJointInterface</hardwareInterface>
      <mechanicalReduction>1</mechanicalReduction>
    </actuator>
  </transmission>  

<!--world/cloister parametres-->
<gazebo reference="front_left_link">
    <mu1>0.2</mu1>
    <mu2>0.2</mu2>
    <kp>10000000</kp>
    <kd>1</kd>
  </gazebo>  
  <gazebo reference="front_right_link">
    <mu1>0.2</mu1>
    <mu2>0.2</mu2>
    <kp>10000000</kp>
    <kd>1</kd>         
  </gazebo>   
  <gazebo reference="rear_left_link">
    <mu1>0.2</mu1>
    <mu2>0.2</mu2>
    <kp>10000000</kp>
    <kd>1</kd>         
  </gazebo> 
  <gazebo reference="rear_right_link">
    <mu1>0.2</mu1>
    <mu2>0.2</mu2>
    <kp>10000000</kp>
    <kd>1</kd>           
  </gazebo>   


  <!-- Gazebo Plugins -->
  <gazebo>
    <plugin name="gazebo_ros_control" filename="libgazebo_ros_control.so">
      <robotNamespace>/</robotNamespace>
      <robotParam>robot_description</robotParam>
      <robotSimType>gazebo_ros_control/DefaultRobotHWSim</robotSimType>
    </plugin>
  </gazebo>

    <gazebo>
    <plugin name="joint_state_publisher" filename="libgazebo_ros_joint_state_publisher.so">
      <jointName>front_left_joint, rear_left_joint, front_right_joint, rear_right_joint</jointName>
      <updateRate>50.0</updateRate>
      <robotNamespace>/</robotNamespace>
      <alwaysOn>true</alwaysOn>
    </plugin>
  </gazebo>

    <gazebo>
    <plugin name="imu_controller" filename="libhector_gazebo_ros_imu.so">
      <robotNamespace>/</robotNamespace>
      <updateRate>50.0</updateRate>
      <bodyName>base_link</bodyName>
      <topicName>imu/data</topicName>
      <accelDrift>0.005 0.005 0.005</accelDrift>
      <accelGaussianNoise>0.005 0.005 0.005</accelGaussianNoise>
      <rateDrift>0.005 0.005 0.005 </rateDrift>
      <rateGaussianNoise>0.005 0.005 0.005 </rateGaussianNoise>
      <headingDrift>0.005</headingDrift>
      <headingGaussianNoise>0.005</headingGaussianNoise>
    </plugin>
  </gazebo>

  <gazebo>
    <plugin name="gps_controller" filename="libhector_gazebo_ros_gps.so">
      <robotNamespace>/</robotNamespace>
      <updateRate>40</updateRate>
      <bodyName>base_link</bodyName>
      <frameId>base_link</frameId>
      <topicName>navsat/fix</topicName>
      <velocityTopicName>navsat/vel</velocityTopicName>
      <referenceLatitude>31.0</referenceLatitude>
      <referenceLongitude>121.4</referenceLongitude>
      <referenceHeading>0</referenceHeading>
      <referenceAltitude>10</referenceAltitude>
      <drift>0.0001 0.0001 0.0001</drift>
    </plugin>
  </gazebo>

  <gazebo>
    <plugin name="magnetic_controller" filename="libhector_gazebo_ros_magnetic.so">
      <updateRate>40</updateRate>
      <bodyName>base_link</bodyName>
      <robotNamespace>/</robotNamespace>
      <topicName>magnetic/fix</topicName>
      <magnitude>1.0</magnitude>
      <referenceHeading>0</referenceHeading>
      <declination>0</declination>
      <inclination>60.0</inclination>
      <!--<offset></offset>-->
      <drift>0.0001 0.0001 0.0001</drift>
      <!--<driftFrequency>/</driftFrequency>-->
      <!--<gaussianNoise>/</gaussianNoise>-->
    </plugin>
  </gazebo>

  <gazebo reference="lidar1_link">
      <sensor type="ray" name="rplidar">
          <pose>0 0 0 0 0 0</pose>
          <visualize>false</visualize>
          <update_rate>5.5</update_rate>
          <ray>
              <scan>
                <horizontal>
                  <samples>360</samples>
                  <resolution>1</resolution>
                  <min_angle>-3.14</min_angle>
                  <max_angle>3.14</max_angle>
                </horizontal>
              </scan>
              <range>
                <min>0.4</min>
                <max>10.0</max>
                <resolution>0.01</resolution>
              </range>
              <noise>
                <type>gaussian</type>
                <mean>0.0</mean>
                <stddev>0.01</stddev>
              </noise>
          </ray>
          <plugin name="gazebo_rplidar" filename="libgazebo_ros_laser.so">
              <topicName>/scan</topicName>
              <frameName>lidar1_link</frameName>
          </plugin>
      </sensor>
  </gazebo>

</robot>